2023-02-17 11:21:27,313 DEBUG    root            Loaded Command Group: ['gcloud', 'auth']
2023-02-17 11:21:27,316 DEBUG    root            Loaded Command Group: ['gcloud', 'auth', 'docker_helper']
2023-02-17 11:21:27,317 DEBUG    root            Running [gcloud.auth.docker-helper] with arguments: [METHOD: "get"]
2023-02-17 11:21:27,375 DEBUG    google.auth.transport.requests Making request: POST https://oauth2.googleapis.com/token
2023-02-17 11:21:27,417 DEBUG    urllib3.connectionpool Starting new HTTPS connection (1): oauth2.googleapis.com:443
2023-02-17 11:21:27,544 DEBUG    urllib3.connectionpool https://oauth2.googleapis.com:443 "POST /token HTTP/1.1" 400 None
2023-02-17 11:21:27,544 DEBUG    google.auth.transport.requests Making request: POST https://oauth2.googleapis.com/token
2023-02-17 11:21:27,595 DEBUG    urllib3.connectionpool https://oauth2.googleapis.com:443 "POST /token HTTP/1.1" 400 None
2023-02-17 11:21:27,596 DEBUG    root            (gcloud.auth.docker-helper) There was a problem refreshing your current auth tokens: ('invalid_grant: Bad Request', {'error': 'invalid_grant', 'error_description': 'Bad Request'})
Please run:

  $ gcloud auth login

to obtain new credentials.

If you have already logged in with a different account:

    $ gcloud config set account ACCOUNT

to select an already authenticated account to use.
Traceback (most recent call last):
  File "/opt/homebrew/Caskroom/google-cloud-sdk/latest/google-cloud-sdk/lib/googlecloudsdk/core/util/retry.py", line 307, in DecoratedFunction
    return retryer.RetryOnException(f, args=args, kwargs=kwargs,
  File "/opt/homebrew/Caskroom/google-cloud-sdk/latest/google-cloud-sdk/lib/googlecloudsdk/core/util/retry.py", line 197, in RetryOnException
    result, exc_info = self.RetryOnResult(
  File "/opt/homebrew/Caskroom/google-cloud-sdk/latest/google-cloud-sdk/lib/googlecloudsdk/core/util/retry.py", line 256, in RetryOnResult
    self._RaiseIfStop(result, state)
  File "/opt/homebrew/Caskroom/google-cloud-sdk/latest/google-cloud-sdk/lib/googlecloudsdk/core/util/retry.py", line 115, in _RaiseIfStop
    raise MaxRetrialsException('Reached', result, state)
googlecloudsdk.core.util.retry.MaxRetrialsException: last_result=(None, (<class 'google.auth.exceptions.RefreshError'>, RefreshError('invalid_grant: Bad Request', {'error': 'invalid_grant', 'error_description': 'Bad Request'}), <traceback object at 0x109a07300>)), last_retrial=1, time_passed_ms=221,time_to_wait=0

During handling of the above exception, another exception occurred:

Traceback (most recent call last):
  File "/opt/homebrew/Caskroom/google-cloud-sdk/latest/google-cloud-sdk/lib/googlecloudsdk/core/credentials/store.py", line 788, in HandleGoogleAuthCredentialsRefreshError
    yield
  File "/opt/homebrew/Caskroom/google-cloud-sdk/latest/google-cloud-sdk/lib/googlecloudsdk/core/credentials/store.py", line 838, in _RefreshGoogleAuth
    credentials.refresh(request_client)
  File "/opt/homebrew/Caskroom/google-cloud-sdk/latest/google-cloud-sdk/lib/googlecloudsdk/core/credentials/creds.py", line 553, in _WrappedRefresh
    orig_refresh(request)
  File "/opt/homebrew/Caskroom/google-cloud-sdk/latest/google-cloud-sdk/lib/googlecloudsdk/core/credentials/google_auth_credentials.py", line 102, in refresh
    return self._Refresh(request)
  File "/opt/homebrew/Caskroom/google-cloud-sdk/latest/google-cloud-sdk/lib/googlecloudsdk/core/credentials/google_auth_credentials.py", line 129, in _Refresh
    access_token, refresh_token, expiry, grant_response = _RefreshGrant(
  File "/opt/homebrew/Caskroom/google-cloud-sdk/latest/google-cloud-sdk/lib/googlecloudsdk/core/credentials/google_auth_credentials.py", line 206, in _RefreshGrant
    response_data = _TokenEndpointRequestWithRetry(request, token_uri, body)
  File "/opt/homebrew/Caskroom/google-cloud-sdk/latest/google-cloud-sdk/lib/googlecloudsdk/core/util/retry.py", line 312, in DecoratedFunction
    exceptions.reraise(to_reraise[1], tb=to_reraise[2])
  File "/opt/homebrew/Caskroom/google-cloud-sdk/latest/google-cloud-sdk/lib/googlecloudsdk/core/exceptions.py", line 146, in reraise
    six.reraise(type(exc_value), exc_value, tb)
  File "/opt/homebrew/Caskroom/google-cloud-sdk/latest/google-cloud-sdk/lib/third_party/six/__init__.py", line 693, in reraise
    raise value
  File "/opt/homebrew/Caskroom/google-cloud-sdk/latest/google-cloud-sdk/lib/googlecloudsdk/core/util/retry.py", line 182, in TryFunc
    return func(*args, **kwargs), None
  File "/opt/homebrew/Caskroom/google-cloud-sdk/latest/google-cloud-sdk/lib/googlecloudsdk/core/credentials/google_auth_credentials.py", line 267, in _TokenEndpointRequestWithRetry
    _HandleErrorResponse(response_body)
  File "/opt/homebrew/Caskroom/google-cloud-sdk/latest/google-cloud-sdk/lib/googlecloudsdk/core/credentials/google_auth_credentials.py", line 296, in _HandleErrorResponse
    google_auth_client._handle_error_response(error_data)  # pylint: disable=protected-access
  File "/opt/homebrew/Caskroom/google-cloud-sdk/latest/google-cloud-sdk/lib/third_party/google/oauth2/_client.py", line 60, in _handle_error_response
    raise exceptions.RefreshError(error_details, response_data)
google.auth.exceptions.RefreshError: ('invalid_grant: Bad Request', {'error': 'invalid_grant', 'error_description': 'Bad Request'})

During handling of the above exception, another exception occurred:

Traceback (most recent call last):
  File "/opt/homebrew/Caskroom/google-cloud-sdk/latest/google-cloud-sdk/lib/googlecloudsdk/calliope/cli.py", line 987, in Execute
    resources = calliope_command.Run(cli=self, args=args)
  File "/opt/homebrew/Caskroom/google-cloud-sdk/latest/google-cloud-sdk/lib/googlecloudsdk/calliope/backend.py", line 809, in Run
    resources = command_instance.Run(args)
  File "/opt/homebrew/Caskroom/google-cloud-sdk/latest/google-cloud-sdk/lib/surface/auth/docker_helper.py", line 66, in Run
    cred = c_store.Load(use_google_auth=True)
  File "/opt/homebrew/Caskroom/google-cloud-sdk/latest/google-cloud-sdk/lib/googlecloudsdk/core/credentials/store.py", line 557, in Load
    cred = _Load(account, scopes, prevent_refresh, use_google_auth)
  File "/opt/homebrew/Caskroom/google-cloud-sdk/latest/google-cloud-sdk/lib/googlecloudsdk/core/credentials/store.py", line 684, in _Load
    RefreshIfAlmostExpire(cred)
  File "/opt/homebrew/Caskroom/google-cloud-sdk/latest/google-cloud-sdk/lib/googlecloudsdk/core/credentials/store.py", line 898, in RefreshIfAlmostExpire
    RefreshIfExpireWithinWindow(credentials, window=_CREDENTIALS_EXPIRY_WINDOW)
  File "/opt/homebrew/Caskroom/google-cloud-sdk/latest/google-cloud-sdk/lib/googlecloudsdk/core/credentials/store.py", line 894, in RefreshIfExpireWithinWindow
    Refresh(credentials)
  File "/opt/homebrew/Caskroom/google-cloud-sdk/latest/google-cloud-sdk/lib/googlecloudsdk/core/credentials/store.py", line 728, in Refresh
    _RefreshGoogleAuth(credentials, http_client, is_impersonated_credential,
  File "/opt/homebrew/Caskroom/google-cloud-sdk/latest/google-cloud-sdk/lib/googlecloudsdk/core/credentials/store.py", line 875, in _RefreshGoogleAuth
    credentials.id_tokenb64 = id_token
  File "/Users/ale/.pyenv/versions/3.8.12/lib/python3.8/contextlib.py", line 131, in __exit__
    self.gen.throw(type, value, traceback)
  File "/opt/homebrew/Caskroom/google-cloud-sdk/latest/google-cloud-sdk/lib/googlecloudsdk/core/credentials/store.py", line 797, in HandleGoogleAuthCredentialsRefreshError
    raise creds_exceptions.TokenRefreshError(six.text_type(e), for_adc=for_adc)
googlecloudsdk.core.credentials.exceptions.TokenRefreshError: There was a problem refreshing your current auth tokens: ('invalid_grant: Bad Request', {'error': 'invalid_grant', 'error_description': 'Bad Request'})
Please run:

  $ gcloud auth login

to obtain new credentials.

If you have already logged in with a different account:

    $ gcloud config set account ACCOUNT

to select an already authenticated account to use.
2023-02-17 11:21:27,603 ERROR    root            (gcloud.auth.docker-helper) There was a problem refreshing your current auth tokens: ('invalid_grant: Bad Request', {'error': 'invalid_grant', 'error_description': 'Bad Request'})
Please run:

  $ gcloud auth login

to obtain new credentials.

If you have already logged in with a different account:

    $ gcloud config set account ACCOUNT

to select an already authenticated account to use.
